[ 2024-05-19 20:33:55,043 ] 97 werkzeug - INFO - [31m[1mWARNING: This is a development server. Do not use it in a production deployment. Use a production WSGI server instead.[0m
 * Running on all addresses (0.0.0.0)
 * Running on http://127.0.0.1:5000
 * Running on http://192.168.1.101:5000
[ 2024-05-19 20:33:55,044 ] 97 werkzeug - INFO - [33mPress CTRL+C to quit[0m
[ 2024-05-19 20:34:05,454 ] 97 werkzeug - INFO - 127.0.0.1 - - [19/May/2024 20:34:05] "GET / HTTP/1.1" 200 -
[ 2024-05-19 20:34:05,563 ] 97 werkzeug - INFO - 127.0.0.1 - - [19/May/2024 20:34:05] "[33mGET /favicon.ico HTTP/1.1[0m" 404 -
[ 2024-05-19 20:35:00,539 ] 97 werkzeug - INFO - 127.0.0.1 - - [19/May/2024 20:35:00] "GET /predictdata HTTP/1.1" 200 -
[ 2024-05-19 20:35:21,255 ] 838 app - ERROR - Exception on /predictdata [POST]
Traceback (most recent call last):
  File "/Users/ibiiziiy/Desktop/mlproject/src/utils.py", line 58, in load_object
    with open(file_path, "rb") as file_obj:
FileNotFoundError: [Errno 2] No such file or directory: 'artifacts/preprocessor.pkl'

During handling of the above exception, another exception occurred:

Traceback (most recent call last):
  File "/Users/ibiiziiy/Desktop/mlproject/src/pipeline/predict_pipeline.py", line 18, in predict
    preprocessor=load_object(file_path=preprocessor_path)
  File "/Users/ibiiziiy/Desktop/mlproject/src/utils.py", line 62, in load_object
    raise CustomException(e, sys)
src.exception.CustomException: Error occured in python script name [/Users/ibiiziiy/Desktop/mlproject/src/utils.py] line number [58] error message[[Errno 2] No such file or directory: 'artifacts/preprocessor.pkl']

During handling of the above exception, another exception occurred:

Traceback (most recent call last):
  File "/opt/anaconda3/envs/venv/lib/python3.9/site-packages/flask/app.py", line 1473, in wsgi_app
    response = self.full_dispatch_request()
  File "/opt/anaconda3/envs/venv/lib/python3.9/site-packages/flask/app.py", line 882, in full_dispatch_request
    rv = self.handle_user_exception(e)
  File "/opt/anaconda3/envs/venv/lib/python3.9/site-packages/flask/app.py", line 880, in full_dispatch_request
    rv = self.dispatch_request()
  File "/opt/anaconda3/envs/venv/lib/python3.9/site-packages/flask/app.py", line 865, in dispatch_request
    return self.ensure_sync(self.view_functions[rule.endpoint])(**view_args)  # type: ignore[no-any-return]
  File "/Users/ibiiziiy/Desktop/mlproject/app.py", line 39, in predict_datapoint
    results=predict_pipeline.predict(pred_df)
  File "/Users/ibiiziiy/Desktop/mlproject/src/pipeline/predict_pipeline.py", line 25, in predict
    raise CustomException(e,sys)
src.exception.CustomException: Error occured in python script name [/Users/ibiiziiy/Desktop/mlproject/src/pipeline/predict_pipeline.py] line number [18] error message[Error occured in python script name [/Users/ibiiziiy/Desktop/mlproject/src/utils.py] line number [58] error message[[Errno 2] No such file or directory: 'artifacts/preprocessor.pkl']]
[ 2024-05-19 20:35:21,258 ] 97 werkzeug - INFO - 127.0.0.1 - - [19/May/2024 20:35:21] "[35m[1mPOST /predictdata HTTP/1.1[0m" 500 -
[ 2024-05-19 20:35:30,687 ] 97 werkzeug - INFO - 127.0.0.1 - - [19/May/2024 20:35:30] "GET /predictdata HTTP/1.1" 200 -
[ 2024-05-19 20:36:04,018 ] 838 app - ERROR - Exception on /predictdata [POST]
Traceback (most recent call last):
  File "/Users/ibiiziiy/Desktop/mlproject/src/utils.py", line 58, in load_object
    with open(file_path, "rb") as file_obj:
FileNotFoundError: [Errno 2] No such file or directory: 'artifacts/preprocessor.pkl'

During handling of the above exception, another exception occurred:

Traceback (most recent call last):
  File "/Users/ibiiziiy/Desktop/mlproject/src/pipeline/predict_pipeline.py", line 18, in predict
    preprocessor=load_object(file_path=preprocessor_path)
  File "/Users/ibiiziiy/Desktop/mlproject/src/utils.py", line 62, in load_object
    raise CustomException(e, sys)
src.exception.CustomException: Error occured in python script name [/Users/ibiiziiy/Desktop/mlproject/src/utils.py] line number [58] error message[[Errno 2] No such file or directory: 'artifacts/preprocessor.pkl']

During handling of the above exception, another exception occurred:

Traceback (most recent call last):
  File "/opt/anaconda3/envs/venv/lib/python3.9/site-packages/flask/app.py", line 1473, in wsgi_app
    response = self.full_dispatch_request()
  File "/opt/anaconda3/envs/venv/lib/python3.9/site-packages/flask/app.py", line 882, in full_dispatch_request
    rv = self.handle_user_exception(e)
  File "/opt/anaconda3/envs/venv/lib/python3.9/site-packages/flask/app.py", line 880, in full_dispatch_request
    rv = self.dispatch_request()
  File "/opt/anaconda3/envs/venv/lib/python3.9/site-packages/flask/app.py", line 865, in dispatch_request
    return self.ensure_sync(self.view_functions[rule.endpoint])(**view_args)  # type: ignore[no-any-return]
  File "/Users/ibiiziiy/Desktop/mlproject/app.py", line 39, in predict_datapoint
    results=predict_pipeline.predict(pred_df)
  File "/Users/ibiiziiy/Desktop/mlproject/src/pipeline/predict_pipeline.py", line 25, in predict
    raise CustomException(e,sys)
src.exception.CustomException: Error occured in python script name [/Users/ibiiziiy/Desktop/mlproject/src/pipeline/predict_pipeline.py] line number [18] error message[Error occured in python script name [/Users/ibiiziiy/Desktop/mlproject/src/utils.py] line number [58] error message[[Errno 2] No such file or directory: 'artifacts/preprocessor.pkl']]
[ 2024-05-19 20:36:04,020 ] 97 werkzeug - INFO - 127.0.0.1 - - [19/May/2024 20:36:04] "[35m[1mPOST /predictdata HTTP/1.1[0m" 500 -
